Workbook

Sheet Recruitment USD
A1: Recruitment Fees
A2: Group 1 (PCP, Nurse, Pharmacist)
A3: LOI | B3: France | C3: Germany | D3: Italy | E3: Spain | F3: UK | G3: US | H3: Canada | I3: Poland | J3: Brazil | K3: Mexico | L3: Argentina | M3: India | N3: China | O3: Russia | P3: Australia | Q3: Indonesia | R3: Japan | S3: Malaysia | T3: Philippines | U3: Singapore | V3: South Korea | W3: Thailand | X3: Turkey | Y3: UAE
A4: 5 minutes | B4: 19 | C4: 19 | D4: 18 | E4: 18 | F4: 19 | G4: 7 | H4: 29 | I4: 17 | J4: 22 | K4: 34 | L4: 51 | M4: 10 | N4: 18 | O4: 30 | P4: 41 | Q4: 40 | R4: 40 | S4: 39 | T4: 32 | U4: 225 | V4: 60 | W4: 32 | X4: 40 | Y4: 50
A5: 10 minutes | B5: 19 | C5: 19 | D5: 18 | E5: 18 | F5: 19 | G5: 7 | H5: 29 | I5: 17 | J5: 25 | K5: 34 | L5: 51 | M5: 10 | N5: 18 | O5: 30 | P5: 41 | Q5: 40 | R5: 40 | S5: 39 | T5: 32 | U5: 225 | V5: 60 | W5: 32 | X5: 40 | Y5: 50
A6: 15 minutes | B6: 19 | C6: 19 | D6: 18 | E6: 18 | F6: 19 | G6: 7 | H6: 29 | I6: 17 | J6: 25 | K6: 34 | L6: 51 | M6: 10 | N6: 18 | O6: 30 | P6: 41 | Q6: 40 | R6: 40 | S6: 39 | T6: 32 | U6: 225 | V6: 60 | W6: 32 | X6: 40 | Y6: 50
A7: 20 minutes | B7: 19 | C7: 19 | D7: 18 | E7: 18 | F7: 19 | G7: 7 | H7: 29 | I7: 17 | J7: 25 | K7: 34 | L7: 51 | M7: 10 | N7: 18 | O7: 30 | P7: 41 | Q7: 40 | R7: 40 | S7: 39 | T7: 32 | U7: 225 | V7: 60 | W7: 32 | X7: 40 | Y7: 50
A8: 25 minutes | B8: 23 | C8: 23 | D8: 22 | E8: 22 | F8: 23 | G8: 11 | H8: 29 | I8: 17 | J8: 25 | K8: 34 | L8: 51 | M8: 10 | N8: 18 | O8: 30 | P8: 41 | Q8: 40 | R8: 40 | S8: 52 | T8: 45 | U8: 225 | V8: 60 | W8: 45 | X8: 40 | Y8: 50
A9: 30 minutes | B9: 23 | C9: 23 | D9: 22 | E9: 22 | F9: 23 | G9: 11 | H9: 29 | I9: 17 | J9: 25 | K9: 34 | L9: 51 | M9: 10 | N9: 18 | O9: 30 | P9: 41 | Q9: 40 | R9: 40 | S9: 52 | T9: 45 | U9: 225 | V9: 60 | W9: 45 | X9: 50 | Y9: 60
A10: 35 minutes | B10: 23 | C10: 23 | D10: 22 | E10: 22 | F10: 23 | G10: 11 | H10: 36 | I10: 17 | J10: 25 | K10: 34 | L10: 60 | M10: 10 | N10: 18 | O10: 30 | P10: 54 | Q10: 40 | R10: 40 | S10: 52 | T10: 45 | U10: 260 | V10: 70 | W10: 45 | X10: 50 | Y10: 60
A11: 40 minutes | B11: 28 | C11: 28 | D11: 27 | E11: 27 | F11: 28 | G11: 15 | H11: 36 | I11: 17 | J11: 25 | K11: 34 | L11: 60 | M11: 10 | N11: 18 | O11: 30 | P11: 54 | Q11: 40 | R11: 40 | S11: 52 | T11: 45 | U11: 260 | V11: 70 | W11: 45 | X11: 50 | Y11: 60
A12: 45 minutes | B12: 28 | C12: 28 | D12: 27 | E12: 27 | F12: 28 | G12: 15 | H12: 36 | I12: 17 | J12: 25 | K12: 34 | L12: 60 | M12: 10 | N12: 18 | O12: 30 | P12: 67 | Q12: 40 | R12: 40 | S12: 52 | T12: 45 | U12: 260 | V12: 70 | W12: 45 | X12: 70 | Y12: 80
A13: 50 minutes | B13: 28 | C13: 28 | D13: 27 | E13: 27 | F13: 28 | G13: 15 | H13: 36 | I13: 17 | J13: 25 | K13: 34 | L13: 60 | M13: 10 | N13: 18 | O13: 30 | P13: 67 | Q13: 40 | R13: 40 | X13: 70 | Y13: 80
A14: 55 minutes | B14: 28 | C14: 28 | D14: 27 | E14: 27 | F14: 28 | G14: 15 | H14: 36 | I14: 17 | J14: 25 | K14: 34 | L14: 60 | M14: 10 | N14: 18 | O14: 30 | P14: 67 | Q14: 40 | R14: 40 | X14: 70 | Y14: 80
A15: 60 minutes | B15: 28 | C15: 28 | D15: 27 | E15: 27 | F15: 28 | G15: 15 | H15: 36 | I15: 17 | J15: 25 | K15: 34 | L15: 60 | M15: 10 | N15: 18 | O15: 30 | P15: 67 | Q15: 40 | R15: 40 | X15: 70 | Y15: 80
A17: Group 2 ( Card, Endos, Pulmos)
A18: LOI | B18: France | C18: Germany | D18: Italy | E18: Spain | F18: UK | G18: US | H18: Canada | I18: Poland | J18: Brazil | K18: Mexico | L18: Argentina | M18: India | N18: China | O18: Russia | P18: Australia | Q18: Indonesia | R18: Japan | S18: Malaysia | T18: Philippines | U18: Singapore | V18: South Korea | W18: Thailand | X18: Turkey | Y18: UAE
A19: 5 minutes | B19: 24 | C19: 24 | D19: 23 | E19: 23 | F19: 24 | G19: 12 | H19: 38 | I19: 26 | J19: 30 | K19: 43 | L19: 60 | M19: 12 | N19: 20 | O19: 35 | P19: 50 | Q19: 50 | R19: 53 | S19: 49 | T19: 42 | U19: 245 | V19: 70 | W19: 42 | X19: 50 | Y19: 65
A20: 10 minutes | B20: 24 | C20: 24 | D20: 23 | E20: 23 | F20: 24 | G20: 12 | H20: 38 | I20: 26 | J20: 30 | K20: 43 | L20: 60 | M20: 12 | N20: 20 | O20: 35 | P20: 50 | Q20: 50 | R20: 53 | S20: 49 | T20: 42 | U20: 245 | V20: 70 | W20: 42 | X20: 50 | Y20: 65
A21: 15 minutes | B21: 24 | C21: 24 | D21: 23 | E21: 23 | F21: 24 | G21: 12 | H21: 38 | I21: 26 | J21: 30 | K21: 43 | L21: 60 | M21: 12 | N21: 20 | O21: 35 | P21: 50 | Q21: 50 | R21: 53 | S21: 49 | T21: 42 | U21: 245 | V21: 70 | W21: 42 | X21: 50 | Y21: 65
A22: 20 minutes | B22: 24 | C22: 24 | D22: 23 | E22: 23 | F22: 24 | G22: 12 | H22: 38 | I22: 26 | J22: 30 | K22: 43 | L22: 60 | M22: 12 | N22: 20 | O22: 35 | P22: 50 | Q22: 50 | R22: 53 | S22: 49 | T22: 42 | U22: 245 | V22: 70 | W22: 42 | X22: 50 | Y22: 65
A23: 25 minutes | B23: 28 | C23: 28 | D23: 27 | E23: 27 | F23: 28 | G23: 16 | H23: 38 | I23: 26 | J23: 30 | K23: 43 | L23: 60 | M23: 12 | N23: 20 | O23: 35 | P23: 50 | Q23: 50 | R23: 53 | S23: 62 | T23: 55 | U23: 245 | V23: 70 | W23: 55 | X23: 50 | Y23: 65
A24: 30 minutes | B24: 28 | C24: 28 | D24: 27 | E24: 27 | F24: 28 | G24: 16 | H24: 38 | I24: 26 | J24: 30 | K24: 43 | L24: 60 | M24: 12 | N24: 20 | O24: 35 | P24: 50 | Q24: 50 | R24: 53 | S24: 62 | T24: 55 | U24: 245 | V24: 70 | W24: 55 | X24: 60 | Y24: 75
A25: 35 minutes | B25: 28 | C25: 28 | D25: 27 | E25: 27 | F25: 28 | G25: 16 | H25: 45 | I25: 30 | J25: 30 | K25: 43 | L25: 68 | M25: 12 | N25: 20 | O25: 35 | P25: 63 | Q25: 60 | R25: 67 | S25: 62 | T25: 55 | U25: 280 | V25: 80 | W25: 55 | X25: 60 | Y25: 75
A26: 40 minutes | B26: 33 | C26: 33 | D26: 31 | E26: 31 | F26: 33 | G26: 20 | H26: 45 | I26: 30 | J26: 30 | K26: 43 | L26: 68 | M26: 12 | N26: 20 | O26: 35 | P26: 63 | Q26: 60 | R26: 67 | S26: 62 | T26: 55 | U26: 280 | V26: 80 | W26: 55 | X26: 60 | Y26: 75
A27: 45 minutes | B27: 33 | C27: 33 | D27: 31 | E27: 31 | F27: 33 | G27: 20 | H27: 45 | I27: 30 | J27: 30 | K27: 43 | L27: 68 | M27: 12 | N27: 20 | O27: 35 | P27: 77 | Q27: 60 | R27: 67 | S27: 62 | T27: 55 | U27: 280 | V27: 80 | W27: 55 | X27: 80 | Y27: 95
A28: 50 minutes | B28: 33 | C28: 33 | D28: 31 | E28: 31 | F28: 33 | G28: 20 | H28: 45 | I28: 30 | J28: 30 | K28: 43 | L28: 68 | M28: 12 | N28: 20 | O28: 35 | P28: 77 | R28: 67 | X28: 80 | Y28: 95
A29: 55 minutes | B29: 33 | C29: 33 | D29: 31 | E29: 31 | F29: 33 | G29: 20 | H29: 45 | I29: 30 | J29: 30 | K29: 43 | L29: 68 | M29: 12 | N29: 20 | O29: 35 | P29: 77 | R29: 67 | X29: 80 | Y29: 95
A30: 60 minutes | B30: 33 | C30: 33 | D30: 31 | E30: 31 | F30: 33 | G30: 20 | H30: 45 | I30: 30 | J30: 30 | K30: 43 | L30: 68 | M30: 12 | N30: 20 | O30: 35 | P30: 77 | R30: 67 | X30: 80 | Y30: 95
A32: Group 3 (Oncos/Hems/ID specialist)
A33: LOI | B33: France | C33: Germany | D33: Italy | E33: Spain | F33: UK | G33: US | H33: Canada | I33: Poland | J33: Brazil | K33: Mexico | L33: Argentina | M33: India | N33: China | O33: Russia | P33: Australia | Q33: Indonesia | R33: Japan | S33: Malaysia | T33: Philippines | U33: Singapore | V33: South Korea | W33: Thailand | X33: Turkey | Y33: UAE
A34: 5 minutes | B34: 24 | C34: 24 | D34: 23 | E34: 23 | F34: 24 | G34: 12 | H34: 52 | I34: 43 | J34: 34 | K34: 51 | L34: 73 | M34: 13 | N34: 24 | O34: 40 | P34: 63 | Q34: 65 | R34: 67 | S34: 64 | T34: 57 | U34: 265 | V34: 85 | W34: 57 | X34: 65 | Y34: 80
A35: 10 minutes | B35: 24 | C35: 24 | D35: 23 | E35: 23 | F35: 24 | G35: 12 | H35: 52 | I35: 43 | J35: 34 | K35: 51 | L35: 73 | M35: 13 | N35: 24 | O35: 40 | P35: 63 | Q35: 65 | R35: 67 | S35: 64 | T35: 57 | U35: 265 | V35: 85 | W35: 57 | X35: 65 | Y35: 80
A36: 15 minutes | B36: 24 | C36: 24 | D36: 23 | E36: 23 | F36: 24 | G36: 12 | H36: 52 | I36: 43 | J36: 34 | K36: 51 | L36: 73 | M36: 13 | N36: 24 | O36: 40 | P36: 63 | Q36: 65 | R36: 67 | S36: 64 | T36: 57 | U36: 265 | V36: 85 | W36: 57 | X36: 65 | Y36: 80
A37: 20 minutes | B37: 24 | C37: 24 | D37: 23 | E37: 23 | F37: 24 | G37: 12 | H37: 52 | I37: 43 | J37: 34 | K37: 51 | L37: 73 | M37: 13 | N37: 24 | O37: 40 | P37: 63 | Q37: 65 | R37: 67 | S37: 64 | T37: 57 | U37: 265 | V37: 85 | W37: 57 | X37: 65 | Y37: 80
A38: 25 minutes | B38: 28 | C38: 28 | D38: 27 | E38: 27 | F38: 28 | G38: 16 | H38: 52 | I38: 43 | J38: 34 | K38: 51 | L38: 73 | M38: 13 | N38: 24 | O38: 40 | P38: 63 | Q38: 65 | R38: 67 | S38: 77 | T38: 70 | U38: 265 | V38: 85 | W38: 70 | X38: 65 | Y38: 80
A39: 30 minutes | B39: 28 | C39: 28 | D39: 27 | E39: 27 | F39: 28 | G39: 16 | H39: 52 | I39: 43 | J39: 34 | K39: 51 | L39: 73 | M39: 13 | N39: 24 | O39: 40 | P39: 63 | Q39: 65 | R39: 67 | S39: 77 | T39: 70 | U39: 265 | V39: 85 | W39: 70 | X39: 75 | Y39: 90
A40: 35 minutes | B40: 28 | C40: 28 | D40: 27 | E40: 27 | F40: 28 | G40: 16 | H40: 59 | I40: 47 | J40: 34 | K40: 51 | L40: 73 | M40: 13 | N40: 24 | O40: 40 | P40: 63 | Q40: 75 | R40: 81 | S40: 77 | T40: 70 | U40: 300 | V40: 95 | W40: 70 | X40: 75 | Y40: 90
A41: 40 minutes | B41: 33 | C41: 33 | D41: 31 | E41: 31 | F41: 33 | G41: 20 | H41: 59 | I41: 47 | J41: 34 | K41: 51 | L41: 81 | M41: 13 | N41: 24 | O41: 40 | P41: 77 | Q41: 75 | R41: 81 | S41: 77 | T41: 70 | U41: 300 | V41: 95 | W41: 70 | X41: 75 | Y41: 90
A42: 45 minutes | B42: 33 | C42: 33 | D42: 31 | E42: 31 | F42: 33 | G42: 20 | H42: 59 | I42: 47 | J42: 34 | K42: 51 | L42: 81 | M42: 13 | N42: 24 | O42: 40 | P42: 77 | Q42: 75 | R42: 81 | S42: 77 | T42: 70 | U42: 300 | V42: 95 | W42: 70 | X42: 95 | Y42: 110
...

Sheet Incentive USD
A1: Incentive Fees
A2: Group 1 ( PCP, Pharmacist)
A3: LOI | B3: France | C3: Germany | D3: Italy | E3: Spain | F3: UK | G3: US | H3: Canada | I3: Poland | J3: Brazil | K3: Mexico | L3: Argentina | M3: India | N3: China | O3: Russia | P3: Australia | Q3: Indonesia | R3: Japan | S3: Malaysia | T3: Philippines | U3: Singapore | V3: South Korea | W3: Thailand | X3: Turkey | Y3: UAE
A4: 5 minutes | B4: 11 | C4: 12 | D4: 9 | E4: 9 | F4: 13 | G4: 8 | H4: 23 | I4: 30 | J4: 15 | K4: 20 | L4: 55 | M4: 8 | N4: 15 | O4: 15 | P4: 45 | Q4: 30 | R4: 30 | S4: 35 | T4: 30 | U4: 55 | V4: 33 | W4: 44 | X4: 35 | Y4: 30
A5: 10 minutes | B5: 22 | C5: 24 | D5: 18 | E5: 17 | F5: 25 | G5: 16 | H5: 33 | I5: 35 | J5: 24 | K5: 30 | L5: 65 | M5: 10 | N5: 20 | O5: 20 | P5: 50 | Q5: 40 | R5: 40 | S5: 45 | T5: 40 | U5: 70 | V5: 43 | W5: 50 | X5: 40 | Y5: 40
A6: 15 minutes | B6: 33 | C6: 36 | D6: 26 | E6: 25 | F6: 38 | G6: 24 | H6: 44 | I6: 40 | J6: 30 | K6: 35 | L6: 75 | M6: 12 | N6: 28 | O6: 28 | P6: 60 | Q6: 50 | R6: 50 | S6: 55 | T6: 50 | U6: 85 | V6: 52 | W6: 60 | X6: 45 | Y6: 50
A7: 20 minutes | B7: 44 | C7: 48 | D7: 35 | E7: 33 | F7: 49 | G7: 32 | H7: 59 | I7: 45 | J7: 36 | K7: 40 | L7: 85 | M7: 14 | N7: 35 | O7: 35 | P7: 70 | Q7: 60 | R7: 60 | S7: 65 | T7: 60 | U7: 100 | V7: 60 | W7: 76 | X7: 50 | Y7: 60
A8: 25 minutes | B8: 55 | C8: 61 | D8: 44 | E8: 42 | F8: 62 | G8: 40 | H8: 80 | I8: 50 | J8: 45 | K8: 50 | L8: 93 | M8: 16 | N8: 43 | O8: 43 | P8: 80 | Q8: 73 | R8: 68 | S8: 78 | T8: 73 | U8: 118 | V8: 70 | W8: 85 | X8: 55 | Y8: 73
A9: 30 minutes | B9: 66 | C9: 73 | D9: 53 | E9: 50 | F9: 74 | G9: 48 | H9: 96 | I9: 65 | J9: 54 | K9: 60 | L9: 100 | M9: 18 | N9: 50 | O9: 50 | P9: 90 | Q9: 85 | R9: 75 | S9: 90 | T9: 85 | U9: 135 | V9: 80 | W9: 95 | X9: 60 | Y9: 85
A10: 35 minutes | B10: 77 | C10: 85 | D10: 62 | E10: 58 | F10: 87 | G10: 56 | H10: 107 | I10: 70 | J10: 63 | K10: 70 | L10: 110 | M10: 21 | N10: 55 | O10: 55 | P10: 113 | Q10: 95 | R10: 85 | S10: 100 | T10: 95 | U10: 145 | V10: 90 | W10: 105 | X10: 68 | Y10: 95
A11: 40 minutes | B11: 88 | C11: 97 | D11: 70 | E11: 66 | F11: 99 | G11: 64 | H11: 123 | I11: 80 | J11: 72 | K11: 80 | L11: 120 | M11: 24 | N11: 60 | O11: 60 | P11: 135 | Q11: 105 | R11: 95 | S11: 110 | T11: 105 | U11: 155 | V11: 100 | W11: 120 | X11: 75 | Y11: 105
A12: 45 minutes | B12: 99 | C12: 109 | D12: 79 | E12: 75 | F12: 112 | G12: 72 | H12: 139 | I12: 90 | J12: 81 | K12: 85 | L12: 133 | M12: 28 | N12: 68 | O12: 68 | P12: 163 | Q12: 115 | R12: 108 | S12: 120 | T12: 115 | U12: 165 | V12: 115 | W12: 135 | X12: 81 | Y12: 118
A13: 50 minutes | B13: 110 | C13: 121 | D13: 88 | E13: 83 | F13: 124 | G13: 80 | H13: 154 | I13: 100 | J13: 90 | K13: 90 | L13: 145 | M13: 32 | N13: 75 | O13: 75 | P13: 190 | R13: 120 | X13: 90 | Y13: 130
A14: 55 minutes | B14: 121 | C14: 133 | D14: 97 | E14: 91 | F14: 137 | G14: 88 | H14: 181 | I14: 110 | J14: 100 | K14: 100 | L14: 158 | M14: 37 | N14: 80 | O14: 80 | P14: 218 | R14: 135 | X14: 96 | Y14: 143
A15: 60 minutes | B15: 132 | C15: 145 | D15: 106 | E15: 99 | F15: 148 | G15: 96 | H15: 196 | I15: 120 | J15: 110 | K15: 110 | L15: 170 | M15: 42 | N15: 85 | O15: 85 | P15: 245 | R15: 150 | X15: 105 | Y15: 155
A17: Group 2 (Card, Endos, Pulmos)
A18: LOI | B18: France | C18: Germany | D18: Italy | E18: Spain | F18: UK | G18: US | H18: Canada | I18: Poland | J18: Brazil | K18: Mexico | L18: Argentina | M18: India | N18: China | O18: Russia | P18: Australia | Q18: Indonesia | R18: Japan | S18: Malaysia | T18: Philippines | U18: Singapore | V18: South Korea | W18: Thailand | X18: Turkey | Y18: UAE
A19: 5 minutes | B19: 13 | C19: 14 | D19: 11 | E19: 10 | F19: 14 | G19: 11 | H19: 30 | I19: 35 | J19: 24 | K19: 30 | L19: 65 | M19: 10 | N19: 20 | O19: 20 | P19: 70 | Q19: 35 | R19: 35 | S19: 40 | T19: 35 | U19: 80 | V19: 45 | W19: 48 | X19: 45 | Y19: 35
A20: 10 minutes | B20: 25 | C20: 28 | D20: 22 | E20: 20 | F20: 29 | G20: 21 | H20: 38 | I20: 45 | J20: 28 | K20: 35 | L20: 75 | M20: 12 | N20: 24 | O20: 24 | P20: 75 | Q20: 45 | R20: 45 | S20: 50 | T20: 45 | U20: 90 | V20: 50 | W20: 54 | X20: 50 | Y20: 45
A21: 15 minutes | B21: 39 | C21: 42 | D21: 33 | E21: 30 | F21: 42 | G21: 32 | H21: 60 | I21: 50 | J21: 37 | K21: 46 | L21: 85 | M21: 14 | N21: 32 | O21: 32 | P21: 95 | Q21: 55 | R21: 55 | S21: 60 | T21: 55 | U21: 103 | V21: 60 | W21: 66 | X21: 55 | Y21: 55
A22: 20 minutes | B22: 51 | C22: 55 | D22: 44 | E22: 40 | F22: 56 | G22: 42 | H22: 80 | I22: 55 | J22: 45 | K22: 56 | L22: 95 | M22: 16 | N22: 40 | O22: 40 | P22: 115 | Q22: 65 | R22: 65 | S22: 70 | T22: 65 | U22: 115 | V22: 70 | W22: 80 | X22: 60 | Y22: 65
A23: 25 minutes | B23: 64 | C23: 69 | D23: 55 | E23: 50 | F23: 70 | G23: 53 | H23: 103 | I23: 60 | J23: 55 | K23: 70 | L23: 108 | M23: 19 | N23: 50 | O23: 50 | P23: 138 | Q23: 78 | R23: 74 | S23: 83 | T23: 78 | U23: 130 | V23: 80 | W23: 91 | X23: 65 | Y23: 78
A24: 30 minutes | B24: 76 | C24: 83 | D24: 66 | E24: 59 | F24: 85 | G24: 63 | H24: 123 | I24: 70 | J24: 65 | K24: 84 | L24: 120 | M24: 22 | N24: 60 | O24: 60 | P24: 160 | Q24: 90 | R24: 83 | S24: 95 | T24: 90 | U24: 145 | V24: 90 | W24: 110 | X24: 70 | Y24: 90
A25: 35 minutes | B25: 89 | C25: 97 | D25: 77 | E25: 69 | F25: 98 | G25: 74 | H25: 145 | I25: 80 | J25: 78 | K25: 98 | L25: 130 | M25: 25 | N25: 66 | O25: 66 | P25: 183 | Q25: 100 | R25: 92 | S25: 105 | T25: 100 | U25: 160 | V25: 100 | W25: 120 | X25: 78 | Y25: 100
A26: 40 minutes | B26: 101 | C26: 110 | D26: 88 | E26: 79 | F26: 112 | G26: 84 | H26: 166 | I26: 90 | J26: 90 | K26: 112 | L26: 140 | M26: 28 | N26: 72 | O26: 72 | P26: 205 | Q26: 110 | R26: 100 | S26: 115 | T26: 110 | U26: 175 | V26: 110 | W26: 135 | X26: 85 | Y26: 110
A27: 45 minutes | B27: 114 | C27: 124 | D27: 99 | E27: 89 | F27: 126 | G27: 95 | H27: 183 | I27: 101 | J27: 100 | K27: 116 | L27: 153 | M27: 32 | N27: 81 | O27: 81 | P27: 225 | Q27: 120 | R27: 118 | S27: 125 | T27: 120 | U27: 190 | V27: 126 | W27: 145 | X27: 93 | Y27: 123
A28: 50 minutes | B28: 127 | C28: 138 | D28: 110 | E28: 99 | F28: 140 | G28: 105 | H28: 203 | I28: 120 | J28: 110 | K28: 120 | L28: 165 | M28: 36 | N28: 90 | O28: 90 | P28: 245 | R28: 135 | X28: 100 | Y28: 135
A29: 55 minutes | B29: 140 | C29: 152 | D29: 121 | E29: 109 | F29: 153 | G29: 116 | H29: 230 | I29: 135 | J29: 121 | K29: 135 | L29: 178 | M29: 41 | N29: 98 | O29: 98 | P29: 273 | R29: 153 | X29: 113 | Y29: 148
A30: 60 minutes | B30: 152 | C30: 165 | D30: 132 | E30: 119 | F30: 168 | G30: 126 | H30: 250 | I30: 161 | J30: 132 | K30: 140 | L30: 190 | M30: 46 | N30: 105 | O30: 105 | P30: 300 | R30: 170 | X30: 125 | Y30: 160
A32: Group 3 (Oncos/Hems/ID specialist)
A33: LOI | B33: France | C33: Germany | D33: Italy | E33: Spain | F33: UK | G33: US | H33: Canada | I33: Poland | J33: Brazil | K33: Mexico | L33: Argentina | M33: India | N33: China | O33: Russia | P33: Australia | Q33: Indonesia | R33: Japan | S33: Malaysia | T33: Philippines | U33: Singapore | V33: South Korea | W33: Thailand | X33: Turkey | Y33: UAE
A34: 5 minutes | B34: 14 | C34: 18 | D34: 12 | E34: 12 | F34: 16 | G34: 12 | H34: 33 | I34: 50 | J34: 28 | K34: 35 | L34: 70 | M34: 12 | N34: 24 | O34: 24 | P34: 75 | Q34: 55 | R34: 40 | S34: 45 | T34: 40 | U34: 85 | V34: 50 | W34: 53 | X34: 45 | Y34: 40
A35: 10 minutes | B35: 28 | C35: 34 | D35: 24 | E35: 23 | F35: 31 | G35: 24 | H35: 42 | I35: 60 | J35: 32 | K35: 40 | L35: 80 | M35: 14 | N35: 30 | O35: 30 | P35: 80 | Q35: 65 | R35: 50 | S35: 55 | T35: 50 | U35: 95 | V35: 55 | W35: 63 | X35: 50 | Y35: 50
A36: 15 minutes | B36: 42 | C36: 52 | D36: 36 | E36: 35 | F36: 47 | G36: 36 | H36: 68 | I36: 70 | J36: 41 | K36: 53 | L36: 95 | M36: 16 | N36: 39 | O36: 39 | P36: 103 | Q36: 68 | R36: 60 | S36: 65 | T36: 60 | U36: 110 | V36: 65 | W36: 73 | X36: 58 | Y36: 60
A37: 20 minutes | B37: 55 | C37: 68 | D37: 48 | E37: 46 | F37: 62 | G37: 48 | H37: 90 | I37: 80 | J37: 50 | K37: 65 | L37: 110 | M37: 18 | N37: 48 | O37: 48 | P37: 125 | Q37: 70 | R37: 70 | S37: 75 | T37: 70 | U37: 125 | V37: 75 | W37: 83 | X37: 65 | Y37: 70
A38: 25 minutes | B38: 69 | C38: 86 | D38: 61 | E38: 58 | F38: 78 | G38: 60 | H38: 115 | I38: 93 | J38: 63 | K38: 83 | L38: 123 | M38: 21 | N38: 60 | O38: 60 | P38: 150 | Q38: 83 | R38: 80 | S38: 88 | T38: 83 | U38: 143 | V38: 85 | W38: 95 | X38: 73 | Y38: 83
A39: 30 minutes | B39: 83 | C39: 102 | D39: 73 | E39: 69 | F39: 94 | G39: 72 | H39: 135 | I39: 105 | J39: 75 | K39: 100 | L39: 135 | M39: 24 | N39: 72 | O39: 72 | P39: 175 | Q39: 95 | R39: 90 | S39: 100 | T39: 95 | U39: 160 | V39: 95 | W39: 115 | X39: 80 | Y39: 95
A40: 35 minutes | B40: 97 | C40: 120 | D40: 85 | E40: 81 | F40: 109 | G40: 84 | H40: 160 | I40: 115 | J40: 88 | K40: 116 | L40: 150 | M40: 28 | N40: 76 | O40: 76 | P40: 203 | Q40: 105 | R40: 103 | S40: 110 | T40: 105 | U40: 175 | V40: 110 | W40: 125 | X40: 88 | Y40: 105
A41: 40 minutes | B41: 110 | C41: 136 | D41: 97 | E41: 92 | F41: 125 | G41: 96 | H41: 185 | I41: 125 | J41: 100 | K41: 132 | L41: 165 | M41: 32 | N41: 80 | O41: 80 | P41: 230 | Q41: 115 | R41: 115 | S41: 120 | T41: 115 | U41: 190 | V41: 125 | W41: 140 | X41: 95 | Y41: 115
A42: 45 minutes | B42: 124 | C42: 154 | D42: 109 | E42: 105 | F42: 140 | G42: 108 | H42: 210 | I42: 138 | J42: 108 | K42: 139 | L42: 178 | M42: 37 | N42: 90 | O42: 90 | P42: 253 | Q42: 125 | R42: 130 | S42: 130 | T42: 120 | U42: 205 | V42: 140 | W42: 150 | X42: 105 | Y42: 128
...

Sheet CPI USD
A1: CPI Fees
A2: Group 1 (PCP, Nurse, Pharmacist)
A3: LOI | B3: France | C3: Germany | D3: Italy | E3: Spain | F3: UK | G3: US | H3: Canada | I3: Poland | J3: Brazil | K3: Mexico | L3: Argentina | M3: India | N3: China | O3: Russia | P3: Australia | Q3: Indonesia | R3: Japan | S3: Malaysia | T3: Philippines | U3: Singapore | V3: South Korea | W3: Thailand | X3: Turkey | Y3: UAE
A4: 5 minutes | B4: ='Recruitment USD'!B4+'Incentive USD'!B4 -> 30 | C4: ='Recruitment USD'!C4+'Incentive USD'!C4 -> 31 | D4: ='Recruitment USD'!D4+'Incentive USD'!D4 -> 27 | E4: ='Recruitment USD'!E4+'Incentive USD'!E4 -> 27 | F4: ='Recruitment USD'!F4+'Incentive USD'!F4 -> 32 | G4: ='Recruitment USD'!G4+'Incentive USD'!G4 -> 15 | H4: ='Recruitment USD'!H4+'Incentive USD'!H4 -> 52 | I4: ='Recruitment USD'!I4+'Incentive USD'!I4 -> 47 | ... Y4: ='Recruitment USD'!Y4+'Incentive USD'!Y4 -> 80
A5: 10 minutes | B5: ='Recruitment USD'!B5+'Incentive USD'!B5 -> 41 | C5: ='Recruitment USD'!C5+'Incentive USD'!C5 -> 43 | D5: ='Recruitment USD'!D5+'Incentive USD'!D5 -> 36 | E5: ='Recruitment USD'!E5+'Incentive USD'!E5 -> 35 | F5: ='Recruitment USD'!F5+'Incentive USD'!F5 -> 44 | G5: ='Recruitment USD'!G5+'Incentive USD'!G5 -> 23 | H5: ='Recruitment USD'!H5+'Incentive USD'!H5 -> 62 | I5: ='Recruitment USD'!I5+'Incentive USD'!I5 -> 52 | ... Y5: ='Recruitment USD'!Y5+'Incentive USD'!Y5 -> 90
A6: 15 minutes | B6: ='Recruitment USD'!B6+'Incentive USD'!B6 -> 52 | C6: ='Recruitment USD'!C6+'Incentive USD'!C6 -> 55 | D6: ='Recruitment USD'!D6+'Incentive USD'!D6 -> 44 | E6: ='Recruitment USD'!E6+'Incentive USD'!E6 -> 43 | F6: ='Recruitment USD'!F6+'Incentive USD'!F6 -> 57 | G6: ='Recruitment USD'!G6+'Incentive USD'!G6 -> 31 | H6: ='Recruitment USD'!H6+'Incentive USD'!H6 -> 73 | I6: ='Recruitment USD'!I6+'Incentive USD'!I6 -> 57 | ... Y6: ='Recruitment USD'!Y6+'Incentive USD'!Y6 -> 100
A7: 20 minutes | B7: ='Recruitment USD'!B7+'Incentive USD'!B7 -> 63 | C7: ='Recruitment USD'!C7+'Incentive USD'!C7 -> 67 | D7: ='Recruitment USD'!D7+'Incentive USD'!D7 -> 53 | E7: ='Recruitment USD'!E7+'Incentive USD'!E7 -> 51 | F7: ='Recruitment USD'!F7+'Incentive USD'!F7 -> 68 | G7: ='Recruitment USD'!G7+'Incentive USD'!G7 -> 39 | H7: ='Recruitment USD'!H7+'Incentive USD'!H7 -> 88 | I7: ='Recruitment USD'!I7+'Incentive USD'!I7 -> 62 | ... Y7: ='Recruitment USD'!Y7+'Incentive USD'!Y7 -> 110
A8: 25 minutes | B8: ='Recruitment USD'!B8+'Incentive USD'!B8 -> 78 | C8: ='Recruitment USD'!C8+'Incentive USD'!C8 -> 84 | D8: ='Recruitment USD'!D8+'Incentive USD'!D8 -> 66 | E8: ='Recruitment USD'!E8+'Incentive USD'!E8 -> 64 | F8: ='Recruitment USD'!F8+'Incentive USD'!F8 -> 85 | G8: ='Recruitment USD'!G8+'Incentive USD'!G8 -> 51 | H8: ='Recruitment USD'!H8+'Incentive USD'!H8 -> 109 | I8: ='Recruitment USD'!I8+'Incentive USD'!I8 -> 67 | ... Y8: ='Recruitment USD'!Y8+'Incentive USD'!Y8 -> 123
A9: 30 minutes | B9: ='Recruitment USD'!B9+'Incentive USD'!B9 -> 89 | C9: ='Recruitment USD'!C9+'Incentive USD'!C9 -> 96 | D9: ='Recruitment USD'!D9+'Incentive USD'!D9 -> 75 | E9: ='Recruitment USD'!E9+'Incentive USD'!E9 -> 72 | F9: ='Recruitment USD'!F9+'Incentive USD'!F9 -> 97 | G9: ='Recruitment USD'!G9+'Incentive USD'!G9 -> 59 | H9: ='Recruitment USD'!H9+'Incentive USD'!H9 -> 125 | I9: ='Recruitment USD'!I9+'Incentive USD'!I9 -> 82 | ... Y9: ='Recruitment USD'!Y9+'Incentive USD'!Y9 -> 145
A10: 35 minutes | B10: ='Recruitment USD'!B10+'Incentive USD'!B10 -> 100 | C10: ='Recruitment USD'!C10+'Incentive USD'!C10 -> 108 | D10: ='Recruitment USD'!D10+'Incentive USD'!D10 -> 84 | E10: ='Recruitment USD'!E10+'Incentive USD'!E10 -> 80 | F10: ='Recruitment USD'!F10+'Incentive USD'!F10 -> 110 | G10: ='Recruitment USD'!G10+'Incentive USD'!G10 -> 67 | H10: ='Recruitment USD'!H10+'Incentive USD'!H10 -> 143 | I10: ='Recruitment USD'!I10+'Incentive USD'!I10 -> 87 | ... Y10: ='Recruitment USD'!Y10+'Incentive USD'!Y10 -> 155
A11: 40 minutes | B11: ='Recruitment USD'!B11+'Incentive USD'!B11 -> 116 | C11: ='Recruitment USD'!C11+'Incentive USD'!C11 -> 125 | D11: ='Recruitment USD'!D11+'Incentive USD'!D11 -> 97 | E11: ='Recruitment USD'!E11+'Incentive USD'!E11 -> 93 | F11: ='Recruitment USD'!F11+'Incentive USD'!F11 -> 127 | G11: ='Recruitment USD'!G11+'Incentive USD'!G11 -> 79 | H11: ='Recruitment USD'!H11+'Incentive USD'!H11 -> 159 | I11: ='Recruitment USD'!I11+'Incentive USD'!I11 -> 97 | ... Y11: ='Recruitment USD'!Y11+'Incentive USD'!Y11 -> 165
A12: 45 minutes | B12: ='Recruitment USD'!B12+'Incentive USD'!B12 -> 127 | C12: ='Recruitment USD'!C12+'Incentive USD'!C12 -> 137 | D12: ='Recruitment USD'!D12+'Incentive USD'!D12 -> 106 | E12: ='Recruitment USD'!E12+'Incentive USD'!E12 -> 102 | F12: ='Recruitment USD'!F12+'Incentive USD'!F12 -> 140 | G12: ='Recruitment USD'!G12+'Incentive USD'!G12 -> 87 | H12: ='Recruitment USD'!H12+'Incentive USD'!H12 -> 175 | I12: ='Recruitment USD'!I12+'Incentive USD'!I12 -> 107 | ... Y12: ='Recruitment USD'!Y12+'Incentive USD'!Y12 -> 198
A13: 50 minutes | B13: ='Recruitment USD'!B13+'Incentive USD'!B13 -> 138 | C13: ='Recruitment USD'!C13+'Incentive USD'!C13 -> 149 | D13: ='Recruitment USD'!D13+'Incentive USD'!D13 -> 115 | E13: ='Recruitment USD'!E13+'Incentive USD'!E13 -> 110 | F13: ='Recruitment USD'!F13+'Incentive USD'!F13 -> 152 | G13: ='Recruitment USD'!G13+'Incentive USD'!G13 -> 95 | H13: ='Recruitment USD'!H13+'Incentive USD'!H13 -> 190 | I13: ='Recruitment USD'!I13+'Incentive USD'!I13 -> 117 | ... Y13: ='Recruitment USD'!Y13+'Incentive USD'!Y13 -> 210
A14: 55 minutes | B14: ='Recruitment USD'!B14+'Incentive USD'!B14 -> 149 | C14: ='Recruitment USD'!C14+'Incentive USD'!C14 -> 161 | D14: ='Recruitment USD'!D14+'Incentive USD'!D14 -> 124 | E14: ='Recruitment USD'!E14+'Incentive USD'!E14 -> 118 | F14: ='Recruitment USD'!F14+'Incentive USD'!F14 -> 165 | G14: ='Recruitment USD'!G14+'Incentive USD'!G14 -> 103 | H14: ='Recruitment USD'!H14+'Incentive USD'!H14 -> 217 | I14: ='Recruitment USD'!I14+'Incentive USD'!I14 -> 127 | ... Y14: ='Recruitment USD'!Y14+'Incentive USD'!Y14 -> 223
A15: 60 minutes | B15: ='Recruitment USD'!B15+'Incentive USD'!B15 -> 160 | C15: ='Recruitment USD'!C15+'Incentive USD'!C15 -> 173 | D15: ='Recruitment USD'!D15+'Incentive USD'!D15 -> 133 | E15: ='Recruitment USD'!E15+'Incentive USD'!E15 -> 126 | F15: ='Recruitment USD'!F15+'Incentive USD'!F15 -> 176 | G15: ='Recruitment USD'!G15+'Incentive USD'!G15 -> 111 | H15: ='Recruitment USD'!H15+'Incentive USD'!H15 -> 232 | I15: ='Recruitment USD'!I15+'Incentive USD'!I15 -> 137 | ... Y15: ='Recruitment USD'!Y15+'Incentive USD'!Y15 -> 235
A17: Group 2 (Card, Endos, Pulmos)
A18: LOI | B18: France | C18: Germany | D18: Italy | E18: Spain | F18: UK | G18: US | H18: Canada | I18: Poland | J18: Brazil | K18: Mexico | L18: Argentina | M18: India | N18: China | O18: Russia | P18: Australia | Q18: Indonesia | R18: Japan | S18: Malaysia | T18: Philippines | U18: Singapore | V18: South Korea | W18: Thailand | X18: Turkey | Y18: UAE
A19: 5 minutes | B19: ='Recruitment USD'!B19+'Incentive USD'!B19 -> 37 | C19: ='Recruitment USD'!C19+'Incentive USD'!C19 -> 38 | D19: ='Recruitment USD'!D19+'Incentive USD'!D19 -> 34 | E19: ='Recruitment USD'!E19+'Incentive USD'!E19 -> 33 | F19: ='Recruitment USD'!F19+'Incentive USD'!F19 -> 38 | G19: ='Recruitment USD'!G19+'Incentive USD'!G19 -> 23 | H19: ='Recruitment USD'!H19+'Incentive USD'!H19 -> 68 | I19: ='Recruitment USD'!I19+'Incentive USD'!I19 -> 61 | ... Y19: ='Recruitment USD'!Y19+'Incentive USD'!Y19 -> 100
A20: 10 minutes | B20: ='Recruitment USD'!B20+'Incentive USD'!B20 -> 49 | C20: ='Recruitment USD'!C20+'Incentive USD'!C20 -> 52 | D20: ='Recruitment USD'!D20+'Incentive USD'!D20 -> 45 | E20: ='Recruitment USD'!E20+'Incentive USD'!E20 -> 43 | F20: ='Recruitment USD'!F20+'Incentive USD'!F20 -> 53 | G20: ='Recruitment USD'!G20+'Incentive USD'!G20 -> 33 | H20: ='Recruitment USD'!H20+'Incentive USD'!H20 -> 76 | I20: ='Recruitment USD'!I20+'Incentive USD'!I20 -> 71 | ... Y20: ='Recruitment USD'!Y20+'Incentive USD'!Y20 -> 110
A21: 15 minutes | B21: ='Recruitment USD'!B21+'Incentive USD'!B21 -> 63 | C21: ='Recruitment USD'!C21+'Incentive USD'!C21 -> 66 | D21: ='Recruitment USD'!D21+'Incentive USD'!D21 -> 56 | E21: ='Recruitment USD'!E21+'Incentive USD'!E21 -> 53 | F21: ='Recruitment USD'!F21+'Incentive USD'!F21 -> 66 | G21: ='Recruitment USD'!G21+'Incentive USD'!G21 -> 44 | H21: ='Recruitment USD'!H21+'Incentive USD'!H21 -> 98 | I21: ='Recruitment USD'!I21+'Incentive USD'!I21 -> 76 | ... Y21: ='Recruitment USD'!Y21+'Incentive USD'!Y21 -> 120
A22: 20 minutes | B22: ='Recruitment USD'!B22+'Incentive USD'!B22 -> 75 | C22: ='Recruitment USD'!C22+'Incentive USD'!C22 -> 79 | D22: ='Recruitment USD'!D22+'Incentive USD'!D22 -> 67 | E22: ='Recruitment USD'!E22+'Incentive USD'!E22 -> 63 | F22: ='Recruitment USD'!F22+'Incentive USD'!F22 -> 80 | G22: ='Recruitment USD'!G22+'Incentive USD'!G22 -> 54 | H22: ='Recruitment USD'!H22+'Incentive USD'!H22 -> 118 | I22: ='Recruitment USD'!I22+'Incentive USD'!I22 -> 81 | ... Y22: ='Recruitment USD'!Y22+'Incentive USD'!Y22 -> 130
A23: 25 minutes | B23: ='Recruitment USD'!B23+'Incentive USD'!B23 -> 92 | C23: ='Recruitment USD'!C23+'Incentive USD'!C23 -> 97 | D23: ='Recruitment USD'!D23+'Incentive USD'!D23 -> 82 | E23: ='Recruitment USD'!E23+'Incentive USD'!E23 -> 77 | F23: ='Recruitment USD'!F23+'Incentive USD'!F23 -> 98 | G23: ='Recruitment USD'!G23+'Incentive USD'!G23 -> 69 | H23: ='Recruitment USD'!H23+'Incentive USD'!H23 -> 141 | I23: ='Recruitment USD'!I23+'Incentive USD'!I23 -> 86 | ... Y23: ='Recruitment USD'!Y23+'Incentive USD'!Y23 -> 143
A24: 30 minutes | B24: ='Recruitment USD'!B24+'Incentive USD'!B24 -> 104 | C24: ='Recruitment USD'!C24+'Incentive USD'!C24 -> 111 | D24: ='Recruitment USD'!D24+'Incentive USD'!D24 -> 93 | E24: ='Recruitment USD'!E24+'Incentive USD'!E24 -> 86 | F24: ='Recruitment USD'!F24+'Incentive USD'!F24 -> 113 | G24: ='Recruitment USD'!G24+'Incentive USD'!G24 -> 79 | H24: ='Recruitment USD'!H24+'Incentive USD'!H24 -> 161 | I24: ='Recruitment USD'!I24+'Incentive USD'!I24 -> 96 | ... Y24: ='Recruitment USD'!Y24+'Incentive USD'!Y24 -> 165
A25: 35 minutes | B25: ='Recruitment USD'!B25+'Incentive USD'!B25 -> 117 | C25: ='Recruitment USD'!C25+'Incentive USD'!C25 -> 125 | D25: ='Recruitment USD'!D25+'Incentive USD'!D25 -> 104 | E25: ='Recruitment USD'!E25+'Incentive USD'!E25 -> 96 | F25: ='Recruitment USD'!F25+'Incentive USD'!F25 -> 126 | G25: ='Recruitment USD'!G25+'Incentive USD'!G25 -> 90 | H25: ='Recruitment USD'!H25+'Incentive USD'!H25 -> 190 | I25: ='Recruitment USD'!I25+'Incentive USD'!I25 -> 110 | ... Y25: ='Recruitment USD'!Y25+'Incentive USD'!Y25 -> 175
A26: 40 minutes | B26: ='Recruitment USD'!B26+'Incentive USD'!B26 -> 134 | C26: ='Recruitment USD'!C26+'Incentive USD'!C26 -> 143 | D26: ='Recruitment USD'!D26+'Incentive USD'!D26 -> 119 | E26: ='Recruitment USD'!E26+'Incentive USD'!E26 -> 110 | F26: ='Recruitment USD'!F26+'Incentive USD'!F26 -> 145 | G26: ='Recruitment USD'!G26+'Incentive USD'!G26 -> 104 | H26: ='Recruitment USD'!H26+'Incentive USD'!H26 -> 211 | I26: ='Recruitment USD'!I26+'Incentive USD'!I26 -> 120 | ... Y26: ='Recruitment USD'!Y26+'Incentive USD'!Y26 -> 185
A27: 45 minutes | B27: ='Recruitment USD'!B27+'Incentive USD'!B27 -> 147 | C27: ='Recruitment USD'!C27+'Incentive USD'!C27 -> 157 | D27: ='Recruitment USD'!D27+'Incentive USD'!D27 -> 130 | E27: ='Recruitment USD'!E27+'Incentive USD'!E27 -> 120 | F27: ='Recruitment USD'!F27+'Incentive USD'!F27 -> 159 | G27: ='Recruitment USD'!G27+'Incentive USD'!G27 -> 115 | H27: ='Recruitment USD'!H27+'Incentive USD'!H27 -> 228 | I27: ='Recruitment USD'!I27+'Incentive USD'!I27 -> 131 | ... Y27: ='Recruitment USD'!Y27+'Incentive USD'!Y27 -> 218
A28: 50 minutes | B28: ='Recruitment USD'!B28+'Incentive USD'!B28 -> 160 | C28: ='Recruitment USD'!C28+'Incentive USD'!C28 -> 171 | D28: ='Recruitment USD'!D28+'Incentive USD'!D28 -> 141 | E28: ='Recruitment USD'!E28+'Incentive USD'!E28 -> 130 | F28: ='Recruitment USD'!F28+'Incentive USD'!F28 -> 173 | G28: ='Recruitment USD'!G28+'Incentive USD'!G28 -> 125 | H28: ='Recruitment USD'!H28+'Incentive USD'!H28 -> 248 | I28: ='Recruitment USD'!I28+'Incentive USD'!I28 -> 150 | ... Y28: ='Recruitment USD'!Y28+'Incentive USD'!Y28 -> 230
A29: 55 minutes | B29: ='Recruitment USD'!B29+'Incentive USD'!B29 -> 173 | C29: ='Recruitment USD'!C29+'Incentive USD'!C29 -> 185 | D29: ='Recruitment USD'!D29+'Incentive USD'!D29 -> 152 | E29: ='Recruitment USD'!E29+'Incentive USD'!E29 -> 140 | F29: ='Recruitment USD'!F29+'Incentive USD'!F29 -> 186 | G29: ='Recruitment USD'!G29+'Incentive USD'!G29 -> 136 | H29: ='Recruitment USD'!H29+'Incentive USD'!H29 -> 275 | I29: ='Recruitment USD'!I29+'Incentive USD'!I29 -> 165 | ... Y29: ='Recruitment USD'!Y29+'Incentive USD'!Y29 -> 243
A30: 60 minutes | B30: ='Recruitment USD'!B30+'Incentive USD'!B30 -> 185 | C30: ='Recruitment USD'!C30+'Incentive USD'!C30 -> 198 | D30: ='Recruitment USD'!D30+'Incentive USD'!D30 -> 163 | E30: ='Recruitment USD'!E30+'Incentive USD'!E30 -> 150 | F30: ='Recruitment USD'!F30+'Incentive USD'!F30 -> 201 | G30: ='Recruitment USD'!G30+'Incentive USD'!G30 -> 146 | H30: ='Recruitment USD'!H30+'Incentive USD'!H30 -> 295 | I30: ='Recruitment USD'!I30+'Incentive USD'!I30 -> 191 | ... Y30: ='Recruitment USD'!Y30+'Incentive USD'!Y30 -> 255
A32: Group 3 (Oncos/Hems/ID specialist)
A33: LOI | B33: France | C33: Germany | D33: Italy | E33: Spain | F33: UK | G33: US | H33: Canada | I33: Poland | J33: Brazil | K33: Mexico | L33: Argentina | M33: India | N33: China | O33: Russia | P33: Australia | Q33: Indonesia | R33: Japan | S33: Malaysia | T33: Philippines | U33: Singapore | V33: South Korea | W33: Thailand | X33: Turkey | Y33: UAE
A34: 5 minutes | B34: ='Recruitment USD'!B34+'Incentive USD'!B34 -> 38 | C34: ='Recruitment USD'!C34+'Incentive USD'!C34 -> 42 | D34: ='Recruitment USD'!D34+'Incentive USD'!D34 -> 35 | E34: ='Recruitment USD'!E34+'Incentive USD'!E34 -> 35 | F34: ='Recruitment USD'!F34+'Incentive USD'!F34 -> 40 | G34: ='Recruitment USD'!G34+'Incentive USD'!G34 -> 24 | H34: ='Recruitment USD'!H34+'Incentive USD'!H34 -> 85 | I34: ='Recruitment USD'!I34+'Incentive USD'!I34 -> 93 | ... Y34: ='Recruitment USD'!Y34+'Incentive USD'!Y34 -> 120
A35: 10 minutes | B35: ='Recruitment USD'!B35+'Incentive USD'!B35 -> 52 | C35: ='Recruitment USD'!C35+'Incentive USD'!C35 -> 58 | D35: ='Recruitment USD'!D35+'Incentive USD'!D35 -> 47 | E35: ='Recruitment USD'!E35+'Incentive USD'!E35 -> 46 | F35: ='Recruitment USD'!F35+'Incentive USD'!F35 -> 55 | G35: ='Recruitment USD'!G35+'Incentive USD'!G35 -> 36 | H35: ='Recruitment USD'!H35+'Incentive USD'!H35 -> 94 | I35: ='Recruitment USD'!I35+'Incentive USD'!I35 -> 103 | ... Y35: ='Recruitment USD'!Y35+'Incentive USD'!Y35 -> 130
A36: 15 minutes | B36: ='Recruitment USD'!B36+'Incentive USD'!B36 -> 66 | C36: ='Recruitment USD'!C36+'Incentive USD'!C36 -> 76 | D36: ='Recruitment USD'!D36+'Incentive USD'!D36 -> 59 | E36: ='Recruitment USD'!E36+'Incentive USD'!E36 -> 58 | F36: ='Recruitment USD'!F36+'Incentive USD'!F36 -> 71 | G36: ='Recruitment USD'!G36+'Incentive USD'!G36 -> 48 | H36: ='Recruitment USD'!H36+'Incentive USD'!H36 -> 120 | I36: ='Recruitment USD'!I36+'Incentive USD'!I36 -> 113 | ... Y36: ='Recruitment USD'!Y36+'Incentive USD'!Y36 -> 140
A37: 20 minutes | B37: ='Recruitment USD'!B37+'Incentive USD'!B37 -> 79 | C37: ='Recruitment USD'!C37+'Incentive USD'!C37 -> 92 | D37: ='Recruitment USD'!D37+'Incentive USD'!D37 -> 71 | E37: ='Recruitment USD'!E37+'Incentive USD'!E37 -> 69 | F37: ='Recruitment USD'!F37+'Incentive USD'!F37 -> 86 | G37: ='Recruitment USD'!G37+'Incentive USD'!G37 -> 60 | H37: ='Recruitment USD'!H37+'Incentive USD'!H37 -> 142 | I37: ='Recruitment USD'!I37+'Incentive USD'!I37 -> 123 | ... Y37: ='Recruitment USD'!Y37+'Incentive USD'!Y37 -> 150
A38: 25 minutes | B38: ='Recruitment USD'!B38+'Incentive USD'!B38 -> 97 | C38: ='Recruitment USD'!C38+'Incentive USD'!C38 -> 114 | D38: ='Recruitment USD'!D38+'Incentive USD'!D38 -> 88 | E38: ='Recruitment USD'!E38+'Incentive USD'!E38 -> 85 | F38: ='Recruitment USD'!F38+'Incentive USD'!F38 -> 106 | G38: ='Recruitment USD'!G38+'Incentive USD'!G38 -> 76 | H38: ='Recruitment USD'!H38+'Incentive USD'!H38 -> 167 | I38: ='Recruitment USD'!I38+'Incentive USD'!I38 -> 136 | ... Y38: ='Recruitment USD'!Y38+'Incentive USD'!Y38 -> 163
A39: 30 minutes | B39: ='Recruitment USD'!B39+'Incentive USD'!B39 -> 111 | C39: ='Recruitment USD'!C39+'Incentive USD'!C39 -> 130 | D39: ='Recruitment USD'!D39+'Incentive USD'!D39 -> 100 | E39: ='Recruitment USD'!E39+'Incentive USD'!E39 -> 96 | F39: ='Recruitment USD'!F39+'Incentive USD'!F39 -> 122 | G39: ='Recruitment USD'!G39+'Incentive USD'!G39 -> 88 | H39: ='Recruitment USD'!H39+'Incentive USD'!H39 -> 187 | I39: ='Recruitment USD'!I39+'Incentive USD'!I39 -> 148 | ... Y39: ='Recruitment USD'!Y39+'Incentive USD'!Y39 -> 185
A40: 35 minutes | B40: ='Recruitment USD'!B40+'Incentive USD'!B40 -> 125 | C40: ='Recruitment USD'!C40+'Incentive USD'!C40 -> 148 | D40: ='Recruitment USD'!D40+'Incentive USD'!D40 -> 112 | E40: ='Recruitment USD'!E40+'Incentive USD'!E40 -> 108 | F40: ='Recruitment USD'!F40+'Incentive USD'!F40 -> 137 | G40: ='Recruitment USD'!G40+'Incentive USD'!G40 -> 100 | H40: ='Recruitment USD'!H40+'Incentive USD'!H40 -> 219 | I40: ='Recruitment USD'!I40+'Incentive USD'!I40 -> 162 | ... Y40: ='Recruitment USD'!Y40+'Incentive USD'!Y40 -> 195
A41: 40 minutes | B41: ='Recruitment USD'!B41+'Incentive USD'!B41 -> 143 | C41: ='Recruitment USD'!C41+'Incentive USD'!C41 -> 169 | D41: ='Recruitment USD'!D41+'Incentive USD'!D41 -> 128 | E41: ='Recruitment USD'!E41+'Incentive USD'!E41 -> 123 | F41: ='Recruitment USD'!F41+'Incentive USD'!F41 -> 158 | G41: ='Recruitment USD'!G41+'Incentive USD'!G41 -> 116 | H41: ='Recruitment USD'!H41+'Incentive USD'!H41 -> 244 | I41: ='Recruitment USD'!I41+'Incentive USD'!I41 -> 172 | ... Y41: ='Recruitment USD'!Y41+'Incentive USD'!Y41 -> 205
A42: 45 minutes | B42: ='Recruitment USD'!B42+'Incentive USD'!B42 -> 157 | C42: ='Recruitment USD'!C42+'Incentive USD'!C42 -> 187 | D42: ='Recruitment USD'!D42+'Incentive USD'!D42 -> 140 | E42: ='Recruitment USD'!E42+'Incentive USD'!E42 -> 136 | F42: ='Recruitment USD'!F42+'Incentive USD'!F42 -> 173 | G42: ='Recruitment USD'!G42+'Incentive USD'!G42 -> 128 | H42: ='Recruitment USD'!H42+'Incentive USD'!H42 -> 269 | I42: ='Recruitment USD'!I42+'Incentive USD'!I42 -> 185 | ... Y42: ='Recruitment USD'!Y42+'Incentive USD'!Y42 -> 238
...

Sheet Groups
A1: Specialty | B1: Recruitment group | C1: Incentive group
A2: Accident & Emergency/Emergency Physician | B2: 3 | C2: 3
A3: Allergy & Immunology | B3: 2 | C3: 2
A4: Anaesthesiology | B4: 2 | C4: 2
A5: Cardiac Surgery | B5: 3 | C5: 3
A6: Cardiology | B6: 2 | C6: 2
A7: Dentistry | B7: 1 | C7: 1
A8: Dermatology | B8: 2 | C8: 2
A9: Diabetes Nurse Educators | B9: 2 | C9: 2
A10: Dietitians | B10: 1 | C10: 1
A11: Endocrinologists/ Diabetologists | B11: 2 | C11: 2
A12: Family Practice, General practice | B12: 1 | C12: 1
A13: Gastroenterology | B13: 3 | C13: 3
... A47: Veterinary | B47: 1 | C47: 1
